Workbook

Sheet archigos 8.0
A1: Unnamed: 0 | B1: obsid | C1: leadid | D1: ccode | E1: idacr | F1: country | G1: continent | H1: leader | I1: startdate | J1: startdate_new | K1: enddate | L1: enddate_new | M1: entry | N1: exit | O1: exitcode | P1: prevtimesinoffice | Q1: posttenurefate | R1: gender | S1: yrborn | T1: yrdied | U1: borndate | V1: ebirthdate | W1: deathdate | X1: edeathdate | Y1: dbpediauri | Z1: numentry | AA1: numexit | AB1: numexitcode | AC1: numposttenurefate | AD1: fties | AE1: ftcur | AF1: start_year | AG1: end_year | AH1: avg_gdp_growth | AI1: avg_gni_per_capita | AJ1: avg_inflation_rate | AK1: avg_child_mortality_rate | AL1: avg_population_growth_rate | AM1: avg_natural_resource_rents | AN1: polity_mean | AO1: was_colonized | AP1: colonial_power | AQ1: colonial_begin | AR1: colonial_end | AS1: colonial_duration | AT1: tenure_days | AU1: tenure_years
A2: 0 | B2: USA-1869 | C2: 81dcc176-1e42-11e4-b4cd-db5882bf8def | D2: 2 | E2: USA | F2: =VLOOKUP(E2,country_continent!A:C,2,FALSE) -> United States of America | G2: =VLOOKUP(E2,country_continent!A:C,3,FALSE) -> North America | H2: Grant | I2: 1869-03-04 | J2: =IF(ISNUMBER(SEARCH("-", I2)), SUBSTITUTE(I2, "-", "/"), I2) -> 1869/03/04 | K2: 1877-03-04 | L2: =IF(ISNUMBER(SEARCH("-", K2)), SUBSTITUTE(K2, "-", "/"), K2) -> 1877/03/04 | M2: Regular | N2: Regular | O2: Regular | P2: 0 | Q2: OK | R2: M | S2: 1822 | T2: 1885 | W2: 1885-07-23 | X2: 23jul1885 | Y2: https://urldefense.proofpoint.com/v2/url?u=http-3A__dbpedia.org_resource_Ulysses-5FS.-5FGrant&d=BQID-g&c=kbmfwr1Yojg42sGEpaQh5ofMHBeTl9EI2eaqQZhHbOU&r=ZliGVSRwfirWoETOrKCh2RSnoygzVPWEk95Me9L-Kwo&m=EaKyFx9mpkhPdFxsxzvW_fiM3jbYwM3xYLjVbSFoDAg&s=x7yRI4mbwG8b0j8c_AwqAahtkPcCfIY2uH8tdRaReBw&e= | Z2: 0 | AA2: 1 | AB2: 0 | AC2: 0 | AF2: 1869 | AG2: 1877 | AO2: FALSE | AT2: 2922 | AU2: =ROUND(AT2/365,3) -> 8.005
A3: 1 | B3: USA-1877 | C3: 81dcc177-1e42-11e4-b4cd-db5882bf8def | D3: 2 | E3: USA | F3: =VLOOKUP(E3,country_continent!A:C,2,FALSE) -> United States of America | G3: =VLOOKUP(E3,country_continent!A:C,3,FALSE) -> North America | H3: Hayes | I3: 1877-03-04 | J3: =IF(ISNUMBER(SEARCH("-", I3)), SUBSTITUTE(I3, "-", "/"), I3) -> 1877/03/04 | K3: 1881-03-04 | L3: =IF(ISNUMBER(SEARCH("-", K3)), SUBSTITUTE(K3, "-", "/"), K3) -> 1881/03/04 | M3: Regular | N3: Regular | O3: Regular | P3: 0 | Q3: OK | R3: M | S3: 1822 | T3: 1893 | W3: 1893-01-17 | X3: 17jan1893 | Y3: https://urldefense.proofpoint.com/v2/url?u=http-3A__dbpedia.org_resource_Rutherford-5FB.-5FHayes&d=BQID-g&c=kbmfwr1Yojg42sGEpaQh5ofMHBeTl9EI2eaqQZhHbOU&r=ZliGVSRwfirWoETOrKCh2RSnoygzVPWEk95Me9L-Kwo&m=EaKyFx9mpkhPdFxsxzvW_fiM3jbYwM3xYLjVbSFoDAg&s=8oshcxB52W-Pg-2a6AvRVJEYMU-S-RG55-369eJ-PyY&e= | Z3: 0 | AA3: 1 | AB3: 0 | AC3: 0 | AF3: 1877 | AG3: 1881 | AO3: FALSE | AT3: 1461 | AU3: =ROUND(AT3/365,3) -> 4.003
A4: 2 | B4: USA-1881-1 | C4: 81dcf24a-1e42-11e4-b4cd-db5882bf8def | D4: 2 | E4: USA | F4: =VLOOKUP(E4,country_continent!A:C,2,FALSE) -> United States of America | G4: =VLOOKUP(E4,country_continent!A:C,3,FALSE) -> North America | H4: Garfield | I4: 1881-03-04 | J4: =IF(ISNUMBER(SEARCH("-", I4)), SUBSTITUTE(I4, "-", "/"), I4) -> 1881/03/04 | K4: 1881-09-19 | L4: =IF(ISNUMBER(SEARCH("-", K4)), SUBSTITUTE(K4, "-", "/"), K4) -> 1881/09/19 | M4: Regular | N4: Irregular | O4: Assassination by Unsupported Individual | P4: 0 | Q4: Death | R4: M | S4: 1831 | T4: 1881 | W4: 1881-09-19 | X4: 19sep1881 | Y4: https://urldefense.proofpoint.com/v2/url?u=http-3A__dbpedia.org_resource_James-5FA.-5FGarfield&d=BQID-g&c=kbmfwr1Yojg42sGEpaQh5ofMHBeTl9EI2eaqQZhHbOU&r=ZliGVSRwfirWoETOrKCh2RSnoygzVPWEk95Me9L-Kwo&m=EaKyFx9mpkhPdFxsxzvW_fiM3jbYwM3xYLjVbSFoDAg&s=qTPSlRS-mPD_m8ZM3luuJ4W47DtmOPoXSnSZn-lYsqM&e= | Z4: 0 | AA4: 3 | AB4: 11 | AC4: 3 | AF4: 1881 | AG4: 1881 | AO4: FALSE | AT4: 199 | AU4: =ROUND(AT4/365,3) -> 0.545
A5: 3 | B5: USA-1881-2 | C5: 81dcf24b-1e42-11e4-b4cd-db5882bf8def | D5: 2 | E5: USA | F5: =VLOOKUP(E5,country_continent!A:C,2,FALSE) -> United States of America | G5: =VLOOKUP(E5,country_continent!A:C,3,FALSE) -> North America | H5: Arthur | I5: 1881-09-19 | J5: =IF(ISNUMBER(SEARCH("-", I5)), SUBSTITUTE(I5, "-", "/"), I5) -> 1881/09/19 | K5: 1885-03-04 | L5: =IF(ISNUMBER(SEARCH("-", K5)), SUBSTITUTE(K5, "-", "/"), K5) -> 1885/03/04 | M5: Regular | N5: Regular | O5: Regular | P5: 0 | Q5: OK | R5: M | S5: 1829 | T5: 1886 | W5: 1886-11-18 | X5: 18nov1886 | Y5: https://urldefense.proofpoint.com/v2/url?u=http-3A__dbpedia.org_resource_Chester-5FA.-5FArthur&d=BQID-g&c=kbmfwr1Yojg42sGEpaQh5ofMHBeTl9EI2eaqQZhHbOU&r=ZliGVSRwfirWoETOrKCh2RSnoygzVPWEk95Me9L-Kwo&m=EaKyFx9mpkhPdFxsxzvW_fiM3jbYwM3xYLjVbSFoDAg&s=XiglK4IJ3ZCC1kR4Hmb8eVB-V7A0tQprCtTKzOl42YM&e= | Z5: 0 | AA5: 1 | AB5: 0 | AC5: 0 | AF5: 1881 | AG5: 1885 | AO5: FALSE | AT5: 1262 | AU5: =ROUND(AT5/365,3) -> 3.458
A6: 4 | B6: USA-1885 | C6: 34fb1558-3bbd-11e5-afeb-eb6f07f9fec7 | D6: 2 | E6: USA | F6: =VLOOKUP(E6,country_continent!A:C,2,FALSE) -> United States of America | G6: =VLOOKUP(E6,country_continent!A:C,3,FALSE) -> North America | H6: Cleveland | I6: 1885-03-04 | J6: =IF(ISNUMBER(SEARCH("-", I6)), SUBSTITUTE(I6, "-", "/"), I6) -> 1885/03/04 | K6: 1889-03-04 | L6: =IF(ISNUMBER(SEARCH("-", K6)), SUBSTITUTE(K6, "-", "/"), K6) -> 1889/03/04 | M6: Regular | N6: Regular | O6: Regular | P6: 0 | Q6: OK | R6: M | S6: 1837 | T6: 1908 | W6: 3098 | X6: 3098 | Y6: https://urldefense.proofpoint.com/v2/url?u=http-3A__dbpedia.org_resource_Grover-5FCleveland&d=BQID-g&c=kbmfwr1Yojg42sGEpaQh5ofMHBeTl9EI2eaqQZhHbOU&r=ZliGVSRwfirWoETOrKCh2RSnoygzVPWEk95Me9L-Kwo&m=EaKyFx9mpkhPdFxsxzvW_fiM3jbYwM3xYLjVbSFoDAg&s=BH6RahZV58hS1fIGz1muHnQkbAirSz4Yy2wc6chejsQ&e= | Z6: 0 | AA6: 1 | AB6: 0 | AC6: 0 | AF6: 1885 | AG6: 1889 | AO6: FALSE | AT6: 1461 | AU6: =ROUND(AT6/365,3) -> 4.003
A7: 5 | B7: USA-1889 | C7: 81dcf24d-1e42-11e4-b4cd-db5882bf8def | D7: 2 | E7: USA | F7: =VLOOKUP(E7,country_continent!A:C,2,FALSE) -> United States of America | G7: =VLOOKUP(E7,country_continent!A:C,3,FALSE) -> North America | H7: Harrison | I7: 1889-03-04 | J7: =IF(ISNUMBER(SEARCH("-", I7)), SUBSTITUTE(I7, "-", "/"), I7) -> 1889/03/04 | K7: 1893-03-04 | L7: =IF(ISNUMBER(SEARCH("-", K7)), SUBSTITUTE(K7, "-", "/"), K7) -> 1893/03/04 | M7: Regular | N7: Regular | O7: Regular | P7: 0 | Q7: OK | R7: M | S7: 1833 | T7: 1901 | W7: 438 | X7: 438 | Y7: https://urldefense.proofpoint.com/v2/url?u=http-3A__dbpedia.org_resource_Benjamin-5FHarrison&d=BQID-g&c=kbmfwr1Yojg42sGEpaQh5ofMHBeTl9EI2eaqQZhHbOU&r=ZliGVSRwfirWoETOrKCh2RSnoygzVPWEk95Me9L-Kwo&m=EaKyFx9mpkhPdFxsxzvW_fiM3jbYwM3xYLjVbSFoDAg&s=MA-TUrYNLJuZ9PTyDnsCkyBUtUyUkXWBHX7_p3f3pnA&e= | Z7: 0 | AA7: 1 | AB7: 0 | AC7: 0 | AF7: 1889 | AG7: 1893 | AO7: FALSE | AT7: 1461 | AU7: =ROUND(AT7/365,3) -> 4.003
A8: 6 | B8: USA-1893 | C8: 34fb1558-3bbd-11e5-afeb-eb6f07f9fec7 | D8: 2 | E8: USA | F8: =VLOOKUP(E8,country_continent!A:C,2,FALSE) -> United States of America | G8: =VLOOKUP(E8,country_continent!A:C,3,FALSE) -> North America | H8: Cleveland | I8: 1893-03-04 | J8: =IF(ISNUMBER(SEARCH("-", I8)), SUBSTITUTE(I8, "-", "/"), I8) -> 1893/03/04 | K8: 1897-03-04 | L8: =IF(ISNUMBER(SEARCH("-", K8)), SUBSTITUTE(K8, "-", "/"), K8) -> 1897/03/04 | M8: Regular | N8: Regular | O8: Regular | P8: 1 | Q8: OK | R8: M | S8: 1837 | T8: 1908 | W8: 3098 | X8: 3098 | Y8: https://urldefense.proofpoint.com/v2/url?u=http-3A__dbpedia.org_resource_Grover-5FCleveland&d=BQID-g&c=kbmfwr1Yojg42sGEpaQh5ofMHBeTl9EI2eaqQZhHbOU&r=ZliGVSRwfirWoETOrKCh2RSnoygzVPWEk95Me9L-Kwo&m=EaKyFx9mpkhPdFxsxzvW_fiM3jbYwM3xYLjVbSFoDAg&s=BH6RahZV58hS1fIGz1muHnQkbAirSz4Yy2wc6chejsQ&e= | Z8: 0 | AA8: 1 | AB8: 0 | AC8: 0 | AF8: 1893 | AG8: 1897 | AO8: FALSE | AT8: 1461 | AU8: =ROUND(AT8/365,3) -> 4.003
A9: 7 | B9: USA-1897 | C9: 81dcf24e-1e42-11e4-b4cd-db5882bf8def | D9: 2 | E9: USA | F9: =VLOOKUP(E9,country_continent!A:C,2,FALSE) -> United States of America | G9: =VLOOKUP(E9,country_continent!A:C,3,FALSE) -> North America | H9: McKinley | I9: 1897-03-04 | J9: =IF(ISNUMBER(SEARCH("-", I9)), SUBSTITUTE(I9, "-", "/"), I9) -> 1897/03/04 | K9: 623 | L9: =IF(ISNUMBER(SEARCH("-", K9)), SUBSTITUTE(K9, "-", "/"), K9) -> 623 | M9: Regular | N9: Irregular | O9: Assassination by Unsupported Individual | P9: 0 | Q9: Death | R9: M | S9: 1843 | T9: 1901 | W9: 623 | X9: 623 | Y9: https://urldefense.proofpoint.com/v2/url?u=http-3A__dbpedia.org_resource_William-5FMcKinley&d=BQID-g&c=kbmfwr1Yojg42sGEpaQh5ofMHBeTl9EI2eaqQZhHbOU&r=ZliGVSRwfirWoETOrKCh2RSnoygzVPWEk95Me9L-Kwo&m=EaKyFx9mpkhPdFxsxzvW_fiM3jbYwM3xYLjVbSFoDAg&s=c1fTbGMfG49MP3oJebg3Hp83_F7aiBUUfKgnhRd8AWs&e= | Z9: 0 | AA9: 3 | AB9: 11 | AC9: 3 | AF9: 1897 | AG9: 1901 | AO9: FALSE | AT9: 1654 | AU9: =ROUND(AT9/365,3) -> 4.532
A10: 8 | B10: USA-1901 | C10: 81dd231e-1e42-11e4-b4cd-db5882bf8def | D10: 2 | E10: USA | F10: =VLOOKUP(E10,country_continent!A:C,2,FALSE) -> United States of America | G10: =VLOOKUP(E10,country_continent!A:C,3,FALSE) -> North America | H10: Roosevelt, T. | I10: 623 | J10: =IF(ISNUMBER(SEARCH("-", I10)), SUBSTITUTE(I10, "-", "/"), I10) -> 623 | K10: 3351 | L10: =IF(ISNUMBER(SEARCH("-", K10)), SUBSTITUTE(K10, "-", "/"), K10) -> 3351 | M10: Regular | N10: Regular | O10: Regular | P10: 0 | Q10: OK | R10: M | S10: 1858 | T10: 1919 | Y10: https://urldefense.proofpoint.com/v2/url?u=http-3A__dbpedia.org_resource_Theodore-5FRoosevelt&d=BQID-g&c=kbmfwr1Yojg42sGEpaQh5ofMHBeTl9EI2eaqQZhHbOU&r=ZliGVSRwfirWoETOrKCh2RSnoygzVPWEk95Me9L-Kwo&m=EaKyFx9mpkhPdFxsxzvW_fiM3jbYwM3xYLjVbSFoDAg&s=mdUxrnAfyEPLl3hgYW-m-YrEL1hVsBHltrXf6_VHzrA&e= | Z10: 0 | AA10: 1 | AB10: 0 | AC10: 0 | AD10: Uncle (distant) of Roosevelt, F.%81dd53f3-1e42-11e4-b4cd-db5882bf8def | AE10: 0 | AF10: 1901 | AG10: 1909 | AO10: FALSE | AT10: 2728 | AU10: =ROUND(AT10/365,3) -> 7.474
A11: 9 | B11: USA-1909 | C11: 81dd231f-1e42-11e4-b4cd-db5882bf8def | D11: 2 | E11: USA | F11: =VLOOKUP(E11,country_continent!A:C,2,FALSE) -> United States of America | G11: =VLOOKUP(E11,country_continent!A:C,3,FALSE) -> North America | H11: Taft | I11: 3351 | J11: =IF(ISNUMBER(SEARCH("-", I11)), SUBSTITUTE(I11, "-", "/"), I11) -> 3351 | K11: 4812 | L11: =IF(ISNUMBER(SEARCH("-", K11)), SUBSTITUTE(K11, "-", "/"), K11) -> 4812 | M11: Regular | N11: Regular | O11: Regular | P11: 0 | Q11: OK | R11: M | S11: 1857 | T11: 1930 | Y11: https://urldefense.proofpoint.com/v2/url?u=http-3A__dbpedia.org_resource_William-5FHoward-5FTaft&d=BQID-g&c=kbmfwr1Yojg42sGEpaQh5ofMHBeTl9EI2eaqQZhHbOU&r=ZliGVSRwfirWoETOrKCh2RSnoygzVPWEk95Me9L-Kwo&m=EaKyFx9mpkhPdFxsxzvW_fiM3jbYwM3xYLjVbSFoDAg&s=bhEfrjiKenGUoUgvh3M4oCxkX9bJoHnDemF4c6OtEtE&e= | Z11: 0 | AA11: 1 | AB11: 0 | AC11: 0 | AF11: 1909 | AG11: 1913 | AO11: FALSE | AT11: 1461 | AU11: =ROUND(AT11/365,3) -> 4.003
A12: 10 | B12: USA-1913 | C12: 81dd2320-1e42-11e4-b4cd-db5882bf8def | D12: 2 | E12: USA | F12: =VLOOKUP(E12,country_continent!A:C,2,FALSE) -> United States of America | G12: =VLOOKUP(E12,country_continent!A:C,3,FALSE) -> North America | H12: Wilson | I12: 4812 | J12: =IF(ISNUMBER(SEARCH("-", I12)), SUBSTITUTE(I12, "-", "/"), I12) -> 4812 | K12: 7734 | L12: =IF(ISNUMBER(SEARCH("-", K12)), SUBSTITUTE(K12, "-", "/"), K12) -> 7734 | M12: Regular | N12: Regular | O12: Regular | P12: 0 | Q12: OK | R12: M | S12: 1856 | T12: 1924 | Y12: https://urldefense.proofpoint.com/v2/url?u=http-3A__dbpedia.org_resource_Woodrow-5FWilson&d=BQID-g&c=kbmfwr1Yojg42sGEpaQh5ofMHBeTl9EI2eaqQZhHbOU&r=ZliGVSRwfirWoETOrKCh2RSnoygzVPWEk95Me9L-Kwo&m=EaKyFx9mpkhPdFxsxzvW_fiM3jbYwM3xYLjVbSFoDAg&s=ClslkAGMxFPwxEqNwig9hoUm-6paj7k9nJQgfZTGBe0&e= | Z12: 0 | AA12: 1 | AB12: 0 | AC12: 0 | AF12: 1913 | AG12: 1921 | AO12: FALSE | AT12: 2922 | AU12: =ROUND(AT12/365,3) -> 8.005
A13: 11 | B13: USA-1921 | C13: 81dd2321-1e42-11e4-b4cd-db5882bf8def | D13: 2 | E13: USA | F13: =VLOOKUP(E13,country_continent!A:C,2,FALSE) -> United States of America | G13: =VLOOKUP(E13,country_continent!A:C,3,FALSE) -> North America | H13: Harding | I13: 7734 | J13: =IF(ISNUMBER(SEARCH("-", I13)), SUBSTITUTE(I13, "-", "/"), I13) -> 7734 | K13: 8616 | L13: =IF(ISNUMBER(SEARCH("-", K13)), SUBSTITUTE(K13, "-", "/"), K13) -> 8616 | M13: Regular | N13: Natural Death | O13: Regular | P13: 0 | Q13: Missing: Natural Death within Six Months of Losing Office | R13: M | S13: 1865 | T13: 1923 | Y13: https://urldefense.proofpoint.com/v2/url?u=http-3A__dbpedia.org_resource_Warren-5FG.-5FHarding&d=BQID-g&c=kbmfwr1Yojg42sGEpaQh5ofMHBeTl9EI2eaqQZhHbOU&r=ZliGVSRwfirWoETOrKCh2RSnoygzVPWEk95Me9L-Kwo&m=EaKyFx9mpkhPdFxsxzvW_fiM3jbYwM3xYLjVbSFoDAg&s=n19WCVJ00e6jAF9KgkqB1QA165ud9DQdOVE8YT4d3LE&e= | Z13: 0 | AA13: 2 | AB13: 0 | AC13: -777 | AF13: 1921 | AG13: 1923 | AO13: FALSE | AT13: 882 | AU13: =ROUND(AT13/365,3) -> 2.416
A14: 12 | B14: USA-1923 | C14: 81dd2322-1e42-11e4-b4cd-db5882bf8def | D14: 2 | E14: USA | F14: =VLOOKUP(E14,country_continent!A:C,2,FALSE) -> United States of America | G14: =VLOOKUP(E14,country_continent!A:C,3,FALSE) -> North America | H14: Coolidge | I14: 8616 | J14: =IF(ISNUMBER(SEARCH("-", I14)), SUBSTITUTE(I14, "-", "/"), I14) -> 8616 | K14: 10656 | L14: =IF(ISNUMBER(SEARCH("-", K14)), SUBSTITUTE(K14, "-", "/"), K14) -> 10656 | M14: Regular | N14: Regular | O14: Regular | P14: 0 | Q14: OK | R14: M | S14: 1872 | T14: 1933 | Y14: https://urldefense.proofpoint.com/v2/url?u=http-3A__dbpedia.org_resource_Calvin-5FCoolidge&d=BQID-g&c=kbmfwr1Yojg42sGEpaQh5ofMHBeTl9EI2eaqQZhHbOU&r=ZliGVSRwfirWoETOrKCh2RSnoygzVPWEk95Me9L-Kwo&m=EaKyFx9mpkhPdFxsxzvW_fiM3jbYwM3xYLjVbSFoDAg&s=NOK4weNtqbdh5IqnE0L5KCW3Toiiym3Zad3PQTU1A-8&e= | Z14: 0 | AA14: 1 | AB14: 0 | AC14: 0 | AF14: 1923 | AG14: 1929 | AO14: FALSE | AT14: 2040 | AU14: =ROUND(AT14/365,3) -> 5.589
A15: 13 | B15: USA-1929 | C15: 81dd53f2-1e42-11e4-b4cd-db5882bf8def | D15: 2 | E15: USA | F15: =VLOOKUP(E15,country_continent!A:C,2,FALSE) -> United States of America | G15: =VLOOKUP(E15,country_continent!A:C,3,FALSE) -> North America | H15: Hoover | I15: 10656 | J15: =IF(ISNUMBER(SEARCH("-", I15)), SUBSTITUTE(I15, "-", "/"), I15) -> 10656 | K15: 12117 | L15: =IF(ISNUMBER(SEARCH("-", K15)), SUBSTITUTE(K15, "-", "/"), K15) -> 12117 | M15: Regular | N15: Regular | O15: Regular | P15: 0 | Q15: OK | R15: M | S15: 1874 | T15: 1964 | Y15: https://urldefense.proofpoint.com/v2/url?u=http-3A__dbpedia.org_resource_Herbert-5FHoover&d=BQID-g&c=kbmfwr1Yojg42sGEpaQh5ofMHBeTl9EI2eaqQZhHbOU&r=ZliGVSRwfirWoETOrKCh2RSnoygzVPWEk95Me9L-Kwo&m=EaKyFx9mpkhPdFxsxzvW_fiM3jbYwM3xYLjVbSFoDAg&s=W0eBFvC2m3N346qhf_r9iGv5N_TNz7Zg6JxS7NQ5y7k&e= | Z15: 0 | AA15: 1 | AB15: 0 | AC15: 0 | AF15: 1929 | AG15: 1933 | AO15: FALSE | AT15: 1461 | AU15: =ROUND(AT15/365,3) -> 4.003
A16: 14 | B16: USA-1933 | C16: 81dd53f3-1e42-11e4-b4cd-db5882bf8def | D16: 2 | E16: USA | F16: =VLOOKUP(E16,country_continent!A:C,2,FALSE) -> United States of America | G16: =VLOOKUP(E16,country_continent!A:C,3,FALSE) -> North America | H16: Roosevelt, F. | I16: 12117 | J16: =IF(ISNUMBER(SEARCH("-", I16)), SUBSTITUTE(I16, "-", "/"), I16) -> 12117 | K16: 16539 | L16: =IF(ISNUMBER(SEARCH("-", K16)), SUBSTITUTE(K16, "-", "/"), K16) -> 16539 | M16: Regular | N16: Natural Death | O16: Regular | P16: 0 | Q16: Missing: Natural Death within Six Months of Losing Office | R16: M | S16: 1882 | T16: 1945 | Y16: https://urldefense.proofpoint.com/v2/url?u=http-3A__dbpedia.org_resource_Franklin-5FD.-5FRoosevelt&d=BQID-g&c=kbmfwr1Yojg42sGEpaQh5ofMHBeTl9EI2eaqQZhHbOU&r=ZliGVSRwfirWoETOrKCh2RSnoygzVPWEk95Me9L-Kwo&m=EaKyFx9mpkhPdFxsxzvW_fiM3jbYwM3xYLjVbSFoDAg&s=leTWvRisdM5Al2qrBj_GjPmFtyEZBnwk2iFJ1n4BAI8&e= | Z16: 0 | AA16: 2 | AB16: 0 | AC16: -777 | AD16: Nephew (distant) of Roosevelt, T.%81dd231e-1e42-11e4-b4cd-db5882bf8def | AE16: 1 | AF16: 1933 | AG16: 1945 | AO16: FALSE | AT16: 4422 | AU16: =ROUND(AT16/365,3) -> 12.115
A17: 15 | B17: USA-1945 | C17: 81dd53f4-1e42-11e4-b4cd-db5882bf8def | D17: 2 | E17: USA | F17: =VLOOKUP(E17,country_continent!A:C,2,FALSE) -> United States of America | G17: =VLOOKUP(E17,country_continent!A:C,3,FALSE) -> North America | H17: Truman | I17: 16539 | J17: =IF(ISNUMBER(SEARCH("-", I17)), SUBSTITUTE(I17, "-", "/"), I17) -> 16539 | K17: 19379 | L17: =IF(ISNUMBER(SEARCH("-", K17)), SUBSTITUTE(K17, "-", "/"), K17) -> 19379 | M17: Regular | N17: Regular | O17: Regular | P17: 0 | Q17: OK | R17: M | S17: 1884 | T17: 1972 | Y17: https://urldefense.proofpoint.com/v2/url?u=http-3A__dbpedia.org_resource_Harry-5FS.-5FTruman&d=BQID-g&c=kbmfwr1Yojg42sGEpaQh5ofMHBeTl9EI2eaqQZhHbOU&r=ZliGVSRwfirWoETOrKCh2RSnoygzVPWEk95Me9L-Kwo&m=EaKyFx9mpkhPdFxsxzvW_fiM3jbYwM3xYLjVbSFoDAg&s=8lvMz1dVajkRMhTCrwHn4rz8eECIgC0MEzNUFYGVA4s&e= | Z17: 0 | AA17: 1 | AB17: 0 | AC17: 0 | AF17: 1945 | AG17: 1953 | AN17: 9 | AO17: FALSE | AT17: 2840 | AU17: =ROUND(AT17/365,3) -> 7.781
A18: 16 | B18: USA-1953 | C18: 81dd53f5-1e42-11e4-b4cd-db5882bf8def | D18: 2 | E18: USA | F18: =VLOOKUP(E18,country_continent!A:C,2,FALSE) -> United States of America | G18: =VLOOKUP(E18,country_continent!A:C,3,FALSE) -> North America | H18: Eisenhower | I18: 19379 | J18: =IF(ISNUMBER(SEARCH("-", I18)), SUBSTITUTE(I18, "-", "/"), I18) -> 19379 | K18: 22301 | L18: =IF(ISNUMBER(SEARCH("-", K18)), SUBSTITUTE(K18, "-", "/"), K18) -> 22301 | M18: Regular | N18: Regular | O18: Regular | P18: 0 | Q18: OK | R18: M | S18: 1890 | T18: 1969 | Y18: https://urldefense.proofpoint.com/v2/url?u=http-3A__dbpedia.org_resource_Dwight-5FD.-5FEisenhower&d=BQID-g&c=kbmfwr1Yojg42sGEpaQh5ofMHBeTl9EI2eaqQZhHbOU&r=ZliGVSRwfirWoETOrKCh2RSnoygzVPWEk95Me9L-Kwo&m=EaKyFx9mpkhPdFxsxzvW_fiM3jbYwM3xYLjVbSFoDAg&s=rbOQoIR9XqJmFi2S0wTaEXDdPmKH7drhnWtGndAuYug&e= | Z18: 0 | AA18: 1 | AB18: 0 | AC18: 0 | AF18: 1953 | AG18: 1961 | AH18: 0.87910227 | AJ18: 1.1389667 | AK18: 29.8 | AL18: 1.65773 | AN18: 9 | AO18: FALSE | AT18: 2922 | AU18: =ROUND(AT18/365,3) -> 8.005
A19: 17 | B19: USA-1961 | C19: 81dd53f6-1e42-11e4-b4cd-db5882bf8def | D19: 2 | E19: USA | F19: =VLOOKUP(E19,country_continent!A:C,2,FALSE) -> United States of America | G19: =VLOOKUP(E19,country_continent!A:C,3,FALSE) -> North America | H19: Kennedy | I19: 22301 | J19: =IF(ISNUMBER(SEARCH("-", I19)), SUBSTITUTE(I19, "-", "/"), I19) -> 22301 | K19: 23337 | L19: =IF(ISNUMBER(SEARCH("-", K19)), SUBSTITUTE(K19, "-", "/"), K19) -> 23337 | M19: Regular | N19: Irregular | O19: Assassination by Unsupported Individual | P19: 0 | Q19: Death | R19: M | S19: 1917 | T19: 1963 | Y19: https://urldefense.proofpoint.com/v2/url?u=http-3A__dbpedia.org_resource_John-5FF.-5FKennedy&d=BQID-g&c=kbmfwr1Yojg42sGEpaQh5ofMHBeTl9EI2eaqQZhHbOU&r=ZliGVSRwfirWoETOrKCh2RSnoygzVPWEk95Me9L-Kwo&m=EaKyFx9mpkhPdFxsxzvW_fiM3jbYwM3xYLjVbSFoDAg&s=fz5b5YwDtYUHk4b8O09aRvlQy8YHM2GtYr6PPuqXASk&e= | Z19: 0 | AA19: 3 | AB19: 11 | AC19: 3 | AF19: 1961 | AG19: 1963 | AH19: 2.7517081 | AI19: 3345 | AJ19: 1.1896244 | AK19: 28.9 | AL19: 1.5449641 | AN19: 9 | AO19: FALSE | AT19: 1036 | AU19: =ROUND(AT19/365,3) -> 2.838
A20: 18 | B20: USA-1963 | C20: 81dd84c6-1e42-11e4-b4cd-db5882bf8def | D20: 2 | E20: USA | F20: =VLOOKUP(E20,country_continent!A:C,2,FALSE) -> United States of America | G20: =VLOOKUP(E20,country_continent!A:C,3,FALSE) -> North America | H20: Johnson | I20: 23337 | J20: =IF(ISNUMBER(SEARCH("-", I20)), SUBSTITUTE(I20, "-", "/"), I20) -> 23337 | K20: 25223 | L20: =IF(ISNUMBER(SEARCH("-", K20)), SUBSTITUTE(K20, "-", "/"), K20) -> 25223 | M20: Regular | N20: Regular | O20: Regular | P20: 0 | Q20: OK | R20: M | S20: 1908 | T20: 1973 | Y20: https://urldefense.proofpoint.com/v2/url?u=http-3A__dbpedia.org_resource_Lyndon-5FB.-5FJohnson&d=BQID-g&c=kbmfwr1Yojg42sGEpaQh5ofMHBeTl9EI2eaqQZhHbOU&r=ZliGVSRwfirWoETOrKCh2RSnoygzVPWEk95Me9L-Kwo&m=EaKyFx9mpkhPdFxsxzvW_fiM3jbYwM3xYLjVbSFoDAg&s=qMRnItod8XC9Z7Sa982pUDwLoBi4BVk8uy8zud2q9ho&e= | Z20: 0 | AA20: 1 | AB20: 0 | AC20: 0 | AF20: 1963 | AG20: 1969 | AH20: 3.6197824 | AI20: 4177.1429 | AJ20: 2.7594151 | AK20: 26.314286 | AL20: 1.1854087 | AN20: 8.57 | AO20: FALSE | AT20: 1886 | AU20: =ROUND(AT20/365,3) -> 5.167
A21: 19 | B21: USA-1969 | C21: 81dd84c7-1e42-11e4-b4cd-db5882bf8def | D21: 2 | E21: USA | F21: =VLOOKUP(E21,country_continent!A:C,2,FALSE) -> United States of America | G21: =VLOOKUP(E21,country_continent!A:C,3,FALSE) -> North America | H21: Nixon | I21: 25223 | J21: =IF(ISNUMBER(SEARCH("-", I21)), SUBSTITUTE(I21, "-", "/"), I21) -> 25223 | K21: 27250 | L21: =IF(ISNUMBER(SEARCH("-", K21)), SUBSTITUTE(K21, "-", "/"), K21) -> 27250 | M21: Regular | N21: Regular | O21: Regular | P21: 0 | Q21: OK | R21: M | S21: 1913 | T21: 1994 | Y21: https://urldefense.proofpoint.com/v2/url?u=http-3A__dbpedia.org_resource_Richard-5FNixon&d=BQID-g&c=kbmfwr1Yojg42sGEpaQh5ofMHBeTl9EI2eaqQZhHbOU&r=ZliGVSRwfirWoETOrKCh2RSnoygzVPWEk95Me9L-Kwo&m=EaKyFx9mpkhPdFxsxzvW_fiM3jbYwM3xYLjVbSFoDAg&s=Oup_2LmC4QJUy7zu8ke76SIe_xdKi4GnqB2hGVHCmBc&e= | Z21: 0 | AA21: 1 | AB21: 0 | AC21: 0 | AF21: 1969 | AG21: 1974 | AH21: 1.7450923 | AI21: 6276.6667 | AJ21: 5.6580824 | AK21: 21.916667 | AL21: 1.0575398 | AM21: 1.2481374 | AN21: 8.33 | AO21: FALSE | AT21: 2027 | AU21: =ROUND(AT21/365,3) -> 5.553
A22: 20 | B22: USA-1974 | C22: 81dd84c8-1e42-11e4-b4cd-db5882bf8def | D22: 2 | E22: USA | F22: =VLOOKUP(E22,country_continent!A:C,2,FALSE) -> United States of America | G22: =VLOOKUP(E22,country_continent!A:C,3,FALSE) -> North America | H22: Ford | I22: 27250 | J22: =IF(ISNUMBER(SEARCH("-", I22)), SUBSTITUTE(I22, "-", "/"), I22) -> 27250 | K22: 28145 | L22: =IF(ISNUMBER(SEARCH("-", K22)), SUBSTITUTE(K22, "-", "/"), K22) -> 28145 | M22: Regular | N22: Regular | O22: Regular | P22: 0 | Q22: OK | R22: M | S22: 1913 | T22: 2006 | Y22: https://urldefense.proofpoint.com/v2/url?u=http-3A__dbpedia.org_resource_Gerald-5FFord&d=BQID-g&c=kbmfwr1Yojg42sGEpaQh5ofMHBeTl9EI2eaqQZhHbOU&r=ZliGVSRwfirWoETOrKCh2RSnoygzVPWEk95Me9L-Kwo&m=EaKyFx9mpkhPdFxsxzvW_fiM3jbYwM3xYLjVbSFoDAg&s=rKHx6vASUC4iuo25L7XbRY9u7foC16KAVPOeee6VzWE&e= | Z22: 0 | AA22: 1 | AB22: 0 | AC22: 0 | AF22: 1974 | AG22: 1977 | AH22: 1.3346656 | AI22: 8835 | AJ22: 7.4945771 | AK22: 18.375 | AL22: 0.96390958 | AM22: 3.1777996 | AN22: 10 | AO22: FALSE | AT22: 895 | AU22: =ROUND(AT22/365,3) -> 2.452
A23: 21 | B23: USA-1977 | C23: 81dd84c9-1e42-11e4-b4cd-db5882bf8def | D23: 2 | E23: USA | F23: =VLOOKUP(E23,country_continent!A:C,2,FALSE) -> United States of America | G23: =VLOOKUP(E23,country_continent!A:C,3,FALSE) -> North America | H23: Carter | I23: 28145 | J23: =IF(ISNUMBER(SEARCH("-", I23)), SUBSTITUTE(I23, "-", "/"), I23) -> 28145 | K23: 29606 | L23: =IF(ISNUMBER(SEARCH("-", K23)), SUBSTITUTE(K23, "-", "/"), K23) -> 29606 | M23: Regular | N23: Regular | O23: Regular | P23: 0 | Q23: OK | R23: M | S23: 1924 | T23: -777 | Z23: 0 | AA23: 1 | AB23: 0 | AC23: 0 | AF23: 1977 | AG23: 1981 | AH23: 2.0721554 | AI23: 12216 | AJ23: 8.007851 | AK23: 15.68 | AL23: 1.0219854 | AM23: 4.1235118 | AN23: 10 | AO23: FALSE | AT23: 1461 | AU23: =ROUND(AT23/365,3) -> 4.003
A24: 22 | B24: USA-1981 | C24: 81dd84ca-1e42-11e4-b4cd-db5882bf8def | D24: 2 | E24: USA | F24: =VLOOKUP(E24,country_continent!A:C,2,FALSE) -> United States of America | G24: =VLOOKUP(E24,country_continent!A:C,3,FALSE) -> North America | H24: Reagan | I24: 29606 | J24: =IF(ISNUMBER(SEARCH("-", I24)), SUBSTITUTE(I24, "-", "/"), I24) -> 29606 | K24: 32528 | L24: =IF(ISNUMBER(SEARCH("-", K24)), SUBSTITUTE(K24, "-", "/"), K24) -> 32528 | M24: Regular | N24: Regular | O24: Regular | P24: 0 | Q24: OK | R24: M | S24: 1911 | T24: 2004 | Y24: https://urldefense.proofpoint.com/v2/url?u=http-3A__dbpedia.org_resource_Ronald-5FReagan&d=BQID-g&c=kbmfwr1Yojg42sGEpaQh5ofMHBeTl9EI2eaqQZhHbOU&r=ZliGVSRwfirWoETOrKCh2RSnoygzVPWEk95Me9L-Kwo&m=EaKyFx9mpkhPdFxsxzvW_fiM3jbYwM3xYLjVbSFoDAg&s=lkRsyOx2c3jHBdhtoz88j8z6MALbfv0cigW48DI3G54&e= | Z24: 0 | AA24: 1 | AB24: 0 | AC24: 0 | AF24: 1981 | AG24: 1989 | AH24: 2.5526741 | AI24: 18471.111 | AJ24: 4.2519358 | AK24: 12.822222 | AL24: 0.91905065 | AM24: 1.9675516 | AN24: 10 | AO24: FALSE | AT24: 2922 | AU24: =ROUND(AT24/365,3) -> 8.005
A25: 23 | B25: USA-1989 | C25: 81ddb59a-1e42-11e4-b4cd-db5882bf8def | D25: 2 | E25: USA | F25: =VLOOKUP(E25,country_continent!A:C,2,FALSE) -> United States of America | G25: =VLOOKUP(E25,country_continent!A:C,3,FALSE) -> North America | H25: G.H.W. Bush | I25: 32528 | J25: =IF(ISNUMBER(SEARCH("-", I25)), SUBSTITUTE(I25, "-", "/"), I25) -> 32528 | K25: 33989 | L25: =IF(ISNUMBER(SEARCH("-", K25)), SUBSTITUTE(K25, "-", "/"), K25) -> 33989 | M25: Regular | N25: Regular | O25: Regular | P25: 0 | Q25: OK | R25: M | S25: 1924 | T25: -777 | Z25: 0 | AA25: 1 | AB25: 0 | AC25: 0 | AD25: Father of G.W. Bush%81ddb59c-1e42-11e4-b4cd-db5882bf8def | AE25: 0 | AF25: 1989 | AG25: 1993 | AH25: 1.1014782 | AI25: 25258 | AJ25: 3.1390158 | AK25: 10.86 | AL25: 1.2231765 | AM25: 1.008135 | AN25: 10 | AO25: FALSE | AT25: 1461 | AU25: =ROUND(AT25/365,3) -> 4.003
A26: 24 | B26: USA-1993 | C26: 81ddb59b-1e42-11e4-b4cd-db5882bf8def | D26: 2 | E26: USA | F26: =VLOOKUP(E26,country_continent!A:C,2,FALSE) -> United States of America | G26: =VLOOKUP(E26,country_continent!A:C,3,FALSE) -> North America | H26: Clinton | I26: 33989 | J26: =IF(ISNUMBER(SEARCH("-", I26)), SUBSTITUTE(I26, "-", "/"), I26) -> 33989 | K26: 36911 | L26: =IF(ISNUMBER(SEARCH("-", K26)), SUBSTITUTE(K26, "-", "/"), K26) -> 36911 | M26: Regular | N26: Regular | O26: Regular | P26: 0 | Q26: OK | R26: M | S26: 1946 | T26: -777 | Y26: https://urldefense.proofpoint.com/v2/url?u=http-3A__dbpedia.org_resource_Bill-5FClinton&d=BQID-g&c=kbmfwr1Yojg42sGEpaQh5ofMHBeTl9EI2eaqQZhHbOU&r=ZliGVSRwfirWoETOrKCh2RSnoygzVPWEk95Me9L-Kwo&m=EaKyFx9mpkhPdFxsxzvW_fiM3jbYwM3xYLjVbSFoDAg&s=q83unszM5hbFxemh6q9IpkwHcXB177RSsz8TJwSDHMM&e= | Z26: 0 | AA26: 1 | AB26: 0 | AC26: 0 | AF26: 1993 | AG26: 2001 | AH26: 2.350748 | AI26: 31528.889 | AJ26: 1.9125859 | AK26: 9.0555556 | AL26: 1.1688556 | AM26: 0.83716593 | AN26: 10 | AO26: FALSE | AT26: 2922 | AU26: =ROUND(AT26/365,3) -> 8.005
A27: 25 | B27: USA-2001 | C27: 81ddb59c-1e42-11e4-b4cd-db5882bf8def | D27: 2 | E27: USA | F27: =VLOOKUP(E27,country_continent!A:C,2,FALSE) -> United States of America | G27: =VLOOKUP(E27,country_continent!A:C,3,FALSE) -> North America | H27: G.W. Bush | I27: 36912 | J27: =IF(ISNUMBER(SEARCH("-", I27)), SUBSTITUTE(I27, "-", "/"), I27) -> 36912 | K27: 39833 | L27: =IF(ISNUMBER(SEARCH("-", K27)), SUBSTITUTE(K27, "-", "/"), K27) -> 39833 | M27: Regular | N27: Regular | O27: Regular | P27: 0 | Q27: OK | R27: M | S27: 1946 | T27: -777 | Y27: https://urldefense.proofpoint.com/v2/url?u=http-3A__dbpedia.org_resource_George-5FW.-5FBush&d=BQID-g&c=kbmfwr1Yojg42sGEpaQh5ofMHBeTl9EI2eaqQZhHbOU&r=ZliGVSRwfirWoETOrKCh2RSnoygzVPWEk95Me9L-Kwo&m=EaKyFx9mpkhPdFxsxzvW_fiM3jbYwM3xYLjVbSFoDAg&s=yGi57JS_o8DCAgvCRWEExDmyN3b0n5O8GhHKvmXjJNI&e= | Z27: 0 | AA27: 1 | AB27: 0 | AC27: 0 | AD27: Son of G.H.W. Bush%81ddb59a-1e42-11e4-b4cd-db5882bf8def | AE27: 1 | AF27: 2001 | AG27: 2009 | AH27: 0.73827017 | AI27: 44054.444 | AJ27: 2.2156808 | AK27: 7.9333333 | AL27: 0.92911594 | AM27: 1.142556 | AN27: 10 | AO27: FALSE | AT27: 2921 | AU27: =ROUND(AT27/365,3) -> 8.003
A28: 26 | B28: USA-2009 | C28: 824fc72f-1e42-11e4-b4cd-db5882bf8def | D28: 2 | E28: USA | F28: =VLOOKUP(E28,country_continent!A:C,2,FALSE) -> United States of America | G28: =VLOOKUP(E28,country_continent!A:C,3,FALSE) -> North America | H28: Obama | I28: 39833 | J28: =IF(ISNUMBER(SEARCH("-", I28)), SUBSTITUTE(I28, "-", "/"), I28) -> 39833 | K28: 42369 | L28: =IF(ISNUMBER(SEARCH("-", K28)), SUBSTITUTE(K28, "-", "/"), K28) -> 42369 | M28: Regular | N28: Still in Office | O28: Still in Office | P28: 0 | Q28: Leader Still in Office | R28: M | S28: 1961 | T28: -777 | U28: 22497 | V28: 22497 | Z28: 0 | AA28: -888 | AB28: -888 | AC28: -888 | AF28: 2009 | AG28: 2015 | AH28: 0.83258764 | AI28: 52200 | AJ28: 1.4469833 | AK28: 7.0714286 | AL28: 0.80914957 | AM28: 0.77324406 | AN28: 10 | AO28: FALSE | AT28: 2536 | AU28: =ROUND(AT28/365,3) -> 6.948
A29: 27 | B29: CAN-1873 | C29: 81ddb59d-1e42-11e4-b4cd-db5882bf8def | D29: 20 | E29: CAN | F29: =VLOOKUP(E29,country_continent!A:C,2,FALSE) -> Canada | G29: =VLOOKUP(E29,country_continent!A:C,3,FALSE) -> North America | H29: Mackenzie | I29: 1873-11-07 | J29: =IF(ISNUMBER(SEARCH("-", I29)), SUBSTITUTE(I29, "-", "/"), I29) -> 1873/11/07 | K29: 1878-10-17 | L29: =IF(ISNUMBER(SEARCH("-", K29)), SUBSTITUTE(K29, "-", "/"), K29) -> 1878/10/17 | M29: Regular | N29: Regular | O29: Regular | P29: 0 | Q29: OK | R29: M | S29: 1822 | T29: 1892 | W29: 1892-04-17 | X29: 17apr1892 | Y29: https://urldefense.proofpoint.com/v2/url?u=http-3A__dbpedia.org_resource_Alexander-5FMackenzie&d=BQID-g&c=kbmfwr1Yojg42sGEpaQh5ofMHBeTl9EI2eaqQZhHbOU&r=ZliGVSRwfirWoETOrKCh2RSnoygzVPWEk95Me9L-Kwo&m=EaKyFx9mpkhPdFxsxzvW_fiM3jbYwM3xYLjVbSFoDAg&s=k6r3Pw-62MkbXzBATsAYVx1IuxSDqmIJjem1sBmmCwM&e= | Z29: 0 | AA29: 1 | AB29: 0 | AC29: 0 | AF29: 1873 | AG29: 1878 | AO29: TRUE | AP29: USA | AQ29: 1920 | AR29: 1959 | AS29: 39骞?1805 | AT29: 4.9418207 | AU29: =ROUND(AT29/365,3) -> 0.014
A30: 28 | B30: CAN-1878 | C30: 197110a8-3bbd-11e5-afeb-eb6f07f9fec7 | D30: 20 | E30: CAN | F30: =VLOOKUP(E30,country_continent!A:C,2,FALSE) -> Canada | G30: =VLOOKUP(E30,country_continent!A:C,3,FALSE) -> North America | H30: Macdonald | I30: 1878-10-17 | J30: =IF(ISNUMBER(SEARCH("-", I30)), SUBSTITUTE(I30, "-", "/"), I30) -> 1878/10/17 | K30: 1891-06-06 | L30: =IF(ISNUMBER(SEARCH("-", K30)), SUBSTITUTE(K30, "-", "/"), K30) -> 1891/06/06 | M30: Regular | N30: Natural Death | O30: Regular | P30: 1 | Q30: Missing: Natural Death within Six Months of Losing Office | R30: M | S30: 1815 | T30: 1891 | W30: 1891-06-06 | X30: 06jun1891 | Y30: https://urldefense.proofpoint.com/v2/url?u=http-3A__dbpedia.org_resource_John-5FA.-5FMacdonald&d=BQID-g&c=kbmfwr1Yojg42sGEpaQh5ofMHBeTl9EI2eaqQZhHbOU&r=ZliGVSRwfirWoETOrKCh2RSnoygzVPWEk95Me9L-Kwo&m=EaKyFx9mpkhPdFxsxzvW_fiM3jbYwM3xYLjVbSFoDAg&s=48mzgFtirP2HSdJCXb_rKfRzyhmk-xDMOoOtUE502mo&e= | Z30: 0 | AA30: 2 | AB30: 0 | AC30: -777 | AF30: 1878 | AG30: 1891 | AO30: TRUE | AP30: USA | AQ30: 1920 | AR30: 1959 | AS30: 39骞?4615 | AT30: 12.635181 | AU30: =ROUND(AT30/365,3) -> 0.035
A31: 29 | B31: CAN-1891 | C31: 81ddb59e-1e42-11e4-b4cd-db5882bf8def | D31: 20 | E31: CAN | F31: =VLOOKUP(E31,country_continent!A:C,2,FALSE) -> Canada | G31: =VLOOKUP(E31,country_continent!A:C,3,FALSE) -> North America | H31: Abbott | I31: 1891-06-16 | J31: =IF(ISNUMBER(SEARCH("-", I31)), SUBSTITUTE(I31, "-", "/"), I31) -> 1891/06/16 | K31: 1892-12-05 | L31: =IF(ISNUMBER(SEARCH("-", K31)), SUBSTITUTE(K31, "-", "/"), K31) -> 1892/12/05 | M31: Regular | N31: Regular | O31: Regular | P31: 0 | Q31: OK | R31: M | S31: 1821 | T31: 1893 | W31: 1893-10-30 | X31: 30oct1893 | Y31: https://urldefense.proofpoint.com/v2/url?u=http-3A__dbpedia.org_resource_John-5FAbbott&d=BQID-g&c=kbmfwr1Yojg42sGEpaQh5ofMHBeTl9EI2eaqQZhHbOU&r=ZliGVSRwfirWoETOrKCh2RSnoygzVPWEk95Me9L-Kwo&m=EaKyFx9mpkhPdFxsxzvW_fiM3jbYwM3xYLjVbSFoDAg&s=tUEQYgkxwyl5E0vwF5BABzdbSh2jlKuHVhC1SRmYCvw&e= | Z31: 0 | AA31: 1 | AB31: 0 | AC31: 0 | AF31: 1891 | AG31: 1892 | AO31: TRUE | AP31: USA | AQ31: 1920 | AR31: 1959 | AS31: 39骞?538 | AT31: 1.4729637 | AU31: =ROUND(AT31/365,3) -> 0.004
A32: 30 | B32: CAN-1892 | C32: 81dde678-1e42-11e4-b4cd-db5882bf8def | D32: 20 | E32: CAN | F32: =VLOOKUP(E32,country_continent!A:C,2,FALSE) -> Canada | G32: =VLOOKUP(E32,country_continent!A:C,3,FALSE) -> North America | H32: Thompson | I32: 1892-12-05 | J32: =IF(ISNUMBER(SEARCH("-", I32)), SUBSTITUTE(I32, "-", "/"), I32) -> 1892/12/05 | K32: 1894-12-12 | L32: =IF(ISNUMBER(SEARCH("-", K32)), SUBSTITUTE(K32, "-", "/"), K32) -> 1894/12/12 | M32: Regular | N32: Natural Death | O32: Regular | P32: 0 | Q32: Missing: Natural Death within Six Months of Losing Office | R32: M | S32: 1845 | T32: 1894 | Z32: 0 | AA32: 2 | AB32: 0 | AC32: -777 | AF32: 1892 | AG32: 1894 | AO32: TRUE | AP32: USA | AQ32: 1920 | AR32: 1959 | AS32: 39骞?737 | AT32: 2.017796 | AU32: =ROUND(AT32/365,3) -> 0.006
A33: 31 | B33: CAN-1894 | C33: 81dde679-1e42-11e4-b4cd-db5882bf8def | D33: 20 | E33: CAN | F33: =VLOOKUP(E33,country_continent!A:C,2,FALSE) -> Canada | G33: =VLOOKUP(E33,country_continent!A:C,3,FALSE) -> North America | H33: Bowell | I33: 1894-12-21 | J33: =IF(ISNUMBER(SEARCH("-", I33)), SUBSTITUTE(I33, "-", "/"), I33) -> 1894/12/21 | K33: 1896-05-01 | L33: =IF(ISNUMBER(SEARCH("-", K33)), SUBSTITUTE(K33, "-", "/"), K33) -> 1896/05/01 | M33: Regular | N33: Regular | O33: Regular | P33: 0 | Q33: OK | R33: M | S33: 1823 | T33: 1917 | Y33: https://urldefense.proofpoint.com/v2/url?u=http-3A__dbpedia.org_resource_Mackenzie-5FBowell&d=BQID-g&c=kbmfwr1Yojg42sGEpaQh5ofMHBeTl9EI2eaqQZhHbOU&r=ZliGVSRwfirWoETOrKCh2RSnoygzVPWEk95Me9L-Kwo&m=EaKyFx9mpkhPdFxsxzvW_fiM3jbYwM3xYLjVbSFoDAg&s=60PEb4noCXilyXVujuhdkkpnfQYWwm9wcV4KEfWb6jg&e= | Z33: 0 | AA33: 1 | AB33: 0 | AC33: 0 | AF33: 1894 | AG33: 1896 | AO33: TRUE | AP33: USA | AQ33: 1920 | AR33: 1959 | AS33: 39骞?497 | AT33: 1.3607118 | AU33: =ROUND(AT33/365,3) -> 0.004
A34: 32 | B34: CAN-1896-1 | C34: 81de174c-1e42-11e4-b4cd-db5882bf8def | D34: 20 | E34: CAN | F34: =VLOOKUP(E34,country_continent!A:C,2,FALSE) -> Canada | G34: =VLOOKUP(E34,country_continent!A:C,3,FALSE) -> North America | H34: Tupper | I34: 1896-05-01 | J34: =IF(ISNUMBER(SEARCH("-", I34)), SUBSTITUTE(I34, "-", "/"), I34) -> 1896/05/01 | K34: 1896-07-11 | L34: =IF(ISNUMBER(SEARCH("-", K34)), SUBSTITUTE(K34, "-", "/"), K34) -> 1896/07/11 | M34: Regular | N34: Regular | O34: Regular | P34: 0 | Q34: OK | R34: M | S34: 1821 | T34: 1915 | Y34: https://urldefense.proofpoint.com/v2/url?u=http-3A__dbpedia.org_resource_Charles-5FTupper&d=BQID-g&c=kbmfwr1Yojg42sGEpaQh5ofMHBeTl9EI2eaqQZhHbOU&r=ZliGVSRwfirWoETOrKCh2RSnoygzVPWEk95Me9L-Kwo&m=EaKyFx9mpkhPdFxsxzvW_fiM3jbYwM3xYLjVbSFoDAg&s=SwNSjv_Nr6aH1NoUFKWaj6wjrNADShiL7oApHYvsyRU&e= | Z34: 0 | AA34: 1 | AB34: 0 | AC34: 0 | AF34: 1896 | AG34: 1896 | AO34: TRUE | AP34: USA | AQ34: 1920 | AR34: 1959 | AS34: 39骞?71 | AT34: 0.19438741 | AU34: =ROUND(AT34/365,3) -> 0.001
A35: 33 | B35: CAN-1896-2 | C35: 81de4820-1e42-11e4-b4cd-db5882bf8def | D35: 20 | E35: CAN | F35: =VLOOKUP(E35,country_continent!A:C,2,FALSE) -> Canada | G35: =VLOOKUP(E35,country_continent!A:C,3,FALSE) -> North America | H35: Laurier | I35: 1896-07-11 | J35: =IF(ISNUMBER(SEARCH("-", I35)), SUBSTITUTE(I35, "-", "/"), I35) -> 1896/07/11 | K35: 4301 | L35: =IF(ISNUMBER(SEARCH("-", K35)), SUBSTITUTE(K35, "-", "/"), K35) -> 4301 | M35: Regular | N35: Regular | O35: Regular | P35: 0 | Q35: OK | R35: M | S35: 1841 | T35: 1919 | Y35: https://urldefense.proofpoint.com/v2/url?u=http-3A__dbpedia.org_resource_Wilfrid-5FLaurier&d=BQID-g&c=kbmfwr1Yojg42sGEpaQh5ofMHBeTl9EI2eaqQZhHbOU&r=ZliGVSRwfirWoETOrKCh2RSnoygzVPWEk95Me9L-Kwo&m=EaKyFx9mpkhPdFxsxzvW_fiM3jbYwM3xYLjVbSFoDAg&s=g09tst56QWN0KuNDYe_u8VrCyLuyc8gLksfx0KF9qDo&e= | Z35: 0 | AA35: 1 | AB35: 0 | AC35: 0 | AF35: 1896 | AG35: 1911 | AO35: TRUE | AP35: USA | AQ35: 1920 | AR35: 1959 | AS35: 39骞?5568 | AT35: 15.244353 | AU35: =ROUND(AT35/365,3) -> 0.042
A36: 34 | B36: CAN-1911 | C36: 81de4821-1e42-11e4-b4cd-db5882bf8def | D36: 20 | E36: CAN | F36: =VLOOKUP(E36,country_continent!A:C,2,FALSE) -> Canada | G36: =VLOOKUP(E36,country_continent!A:C,3,FALSE) -> North America | H36: Borden | I36: 4301 | J36: =IF(ISNUMBER(SEARCH("-", I36)), SUBSTITUTE(I36, "-", "/"), I36) -> 4301 | K36: 7467 | L36: =IF(ISNUMBER(SEARCH("-", K36)), SUBSTITUTE(K36, "-", "/"), K36) -> 7467 | M36: Regular | N36: Retired Due to Ill Health | O36: Regular | P36: 0 | Q36: OK | R36: M | S36: 1854 | T36: 1937 | Y36: https://urldefense.proofpoint.com/v2/url?u=http-3A__dbpedia.org_resource_Robert-5FBorden&d=BQID-g&c=kbmfwr1Yojg42sGEpaQh5ofMHBeTl9EI2eaqQZhHbOU&r=ZliGVSRwfirWoETOrKCh2RSnoygzVPWEk95Me9L-Kwo&m=EaKyFx9mpkhPdFxsxzvW_fiM3jbYwM3xYLjVbSFoDAg&s=3oDRQ0WFDLF-y9CZ9MpmZBulifIpPh6oUY9zPdR0D30&e= | Z36: 0 | AA36: 2.0999999 | AB36: 0 | AC36: 0 | AF36: 1911 | AG36: 1920 | AO36: TRUE | AP36: USA | AQ36: 1920 | AR36: 1959 | AS36: 39骞?3166 | AT36: 8.6680356 | AU36: =ROUND(AT36/365,3) -> 0.024
A37: 35 | B37: CAN-1920 | C37: 81de4822-1e42-11e4-b4cd-db5882bf8def | D37: 20 | E37: CAN | F37: =VLOOKUP(E37,country_continent!A:C,2,FALSE) -> Canada | G37: =VLOOKUP(E37,country_continent!A:C,3,FALSE) -> North America | H37: Meighen | I37: 7497 | J37: =IF(ISNUMBER(SEARCH("-", I37)), SUBSTITUTE(I37, "-", "/"), I37) -> 7497 | K37: 8034 | L37: =IF(ISNUMBER(SEARCH("-", K37)), SUBSTITUTE(K37, "-", "/"), K37) -> 8034 | M37: Regular | N37: Regular | O37: Regular | P37: 0 | Q37: OK | R37: M | S37: 1874 | T37: 1960 | Y37: https://urldefense.proofpoint.com/v2/url?u=http-3A__dbpedia.org_resource_Arthur-5FMeighen&d=BQID-g&c=kbmfwr1Yojg42sGEpaQh5ofMHBeTl9EI2eaqQZhHbOU&r=ZliGVSRwfirWoETOrKCh2RSnoygzVPWEk95Me9L-Kwo&m=EaKyFx9mpkhPdFxsxzvW_fiM3jbYwM3xYLjVbSFoDAg&s=beEjK11YQvAxkxJNw0MD71hEGdO1cPM93XBAjOSu95M&e= | Z37: 0 | AA37: 1 | AB37: 0 | AC37: 0 | AF37: 1920 | AG37: 1921 | AO37: TRUE | AP37: USA | AQ37: 1920 | AR37: 1959 | AS37: 39骞?537 | AT37: 1.4702259 | AU37: =ROUND(AT37/365,3) -> 0.004
A38: 36 | B38: CAN-1921 | C38: 81de4823-1e42-11e4-b4cd-db5882bf8def | D38: 20 | E38: CAN | F38: =VLOOKUP(E38,country_continent!A:C,2,FALSE) -> Canada | G38: =VLOOKUP(E38,country_continent!A:C,3,FALSE) -> North America | H38: King | I38: 8034 | J38: =IF(ISNUMBER(SEARCH("-", I38)), SUBSTITUTE(I38, "-", "/"), I38) -> 8034 | K38: 9676 | L38: =IF(ISNUMBER(SEARCH("-", K38)), SUBSTITUTE(K38, "-", "/"), K38) -> 9676 | M38: Regular | N38: Regular | O38: Regular | P38: 0 | Q38: OK | R38: M | S38: 1874 | T38: 1951 | Z38: 0 | AA38: 1 | AB38: 0 | AC38: 0 | AD38: Father of Ramon Baez%81e1556e-1e42-11e4-b4cd-db5882bf8def | AE38: 1 | AF38: 1921 | AG38: 1926 | AO38: TRUE | AP38: USA | AQ38: 1920 | AR38: 1959 | AS38: 39骞?1642 | AT38: 4.495551 | AU38: =ROUND(AT38/365,3) -> 0.012
A39: 37 | B39: CAN-1926-1 | C39: 81de4822-1e42-11e4-b4cd-db5882bf8def | D39: 20 | E39: CAN | F39: =VLOOKUP(E39,country_continent!A:C,2,FALSE) -> Canada | G39: =VLOOKUP(E39,country_continent!A:C,3,FALSE) -> North America | H39: Meighen | I39: 9677 | J39: =IF(ISNUMBER(SEARCH("-", I39)), SUBSTITUTE(I39, "-", "/"), I39) -> 9677 | K39: 9765 | L39: =IF(ISNUMBER(SEARCH("-", K39)), SUBSTITUTE(K39, "-", "/"), K39) -> 9765 | M39: Regular | N39: Regular | O39: Regular | P39: 1 | Q39: OK | R39: M | S39: 1874 | T39: 1960 | Y39: https://urldefense.proofpoint.com/v2/url?u=http-3A__dbpedia.org_resource_Arthur-5FMeighen&d=BQID-g&c=kbmfwr1Yojg42sGEpaQh5ofMHBeTl9EI2eaqQZhHbOU&r=ZliGVSRwfirWoETOrKCh2RSnoygzVPWEk95Me9L-Kwo&m=EaKyFx9mpkhPdFxsxzvW_fiM3jbYwM3xYLjVbSFoDAg&s=beEjK11YQvAxkxJNw0MD71hEGdO1cPM93XBAjOSu95M&e= | Z39: 0 | AA39: 1 | AB39: 0 | AC39: 0 | AF39: 1926 | AG39: 1926 | AO39: TRUE | AP39: USA | AQ39: 1920 | AR39: 1959 | AS39: 39骞?88 | AT39: 0.24093087 | AU39: =ROUND(AT39/365,3) -> 0.001
A40: 38 | B40: CAN-1926-2 | C40: 81de4823-1e42-11e4-b4cd-db5882bf8def | D40: 20 | E40: CAN | F40: =VLOOKUP(E40,country_continent!A:C,2,FALSE) -> Canada | G40: =VLOOKUP(E40,country_continent!A:C,3,FALSE) -> North America | H40: King | I40: 9765 | J40: =IF(ISNUMBER(SEARCH("-", I40)), SUBSTITUTE(I40, "-", "/"), I40) -> 9765 | K40: 11177 | L40: =IF(ISNUMBER(SEARCH("-", K40)), SUBSTITUTE(K40, "-", "/"), K40) -> 11177 | M40: Regular | N40: Regular | O40: Regular | P40: 1 | Q40: OK | R40: M | S40: 1874 | T40: 1951 | Z40: 0 | AA40: 1 | AB40: 0 | AC40: 0 | AD40: Father of Ramon Baez%81e1556e-1e42-11e4-b4cd-db5882bf8def | AE40: 1 | AF40: 1926 | AG40: 1930 | AO40: TRUE | AP40: USA | AQ40: 1920 | AR40: 1959 | AS40: 39骞?1412 | AT40: 3.8658453 | AU40: =ROUND(AT40/365,3) -> 0.011
...

Sheet Sheet1
A1: Unnamed: 0 | B1: obsid | C1: leadid | D1: ccode | E1: idacr | F1: country | G1: continent | H1: leader | I1: startdate | J1: startdate_new | K1: enddate | L1: enddate_new | M1: entry | N1: exit | O1: exitcode | P1: prevtimesinoffice | Q1: posttenurefate | R1: gender | S1: yrborn | T1: yrdied | U1: borndate | V1: ebirthdate | W1: deathdate | X1: edeathdate | Y1: dbpediauri | Z1: numentry | AA1: numexit | AB1: numexitcode | AC1: numposttenurefate | AD1: fties | AE1: ftcur | AF1: start_year | AG1: end_year | AH1: avg_gdp_growth | AI1: avg_gni_per_capita | AJ1: avg_inflation_rate | AK1: avg_child_mortality_rate | AL1: avg_population_growth_rate | AM1: avg_natural_resource_rents | AN1: polity_mean | AO1: was_colonized | AP1: colonial_power | AQ1: colonial_begin | AR1: colonial_end | AS1: colonial_duration | AT1: tenure_days | AU1: tenure_years
A2: 1550 | B2: POL-1918-1 | C2: 8214746a-1e42-11e4-b4cd-db5882bf8def | D2: 290 | E2: POL | F2: =VLOOKUP(E2,country_continent!A:C,2,FALSE) -> Poland | G2: =VLOOKUP(E2,country_continent!A:C,3,FALSE) -> Europe | H2: Daszynski | I2: 6890 | J2: =IF(ISNUMBER(SEARCH("-", I2)), SUBSTITUTE(I2, "-", "/"), I2) -> 6890 | K2: 6892 | L2: =IF(ISNUMBER(SEARCH("-", K2)), SUBSTITUTE(K2, "-", "/"), K2) -> 6892 | M2: Irregular | N2: Regular | O2: Regular | P2: 0 | Q2: OK | R2: M | S2: 1866 | T2: 1936 | U2: 1866-10-26 | V2: 26oct1866 | W2: 13454 | X2: 13454 | Y2: https://urldefense.proofpoint.com/v2/url?u=http-3A__dbpedia.org_resource_Ignacy-5FDaszy-25C5-2584ski&d=BQID-g&c=kbmfwr1Yojg42sGEpaQh5ofMHBeTl9EI2eaqQZhHbOU&r=ZliGVSRwfirWoETOrKCh2RSnoygzVPWEk95Me9L-Kwo&m=EaKyFx9mpkhPdFxsxzvW_fiM3jbYwM3xYLjVbSFoDAg&s=8XEXIOEYa44vTzEptqHAqdRTZROWXXa4P9hEqNs51vk&e= | Z2: 1 | AA2: 1 | AB2: 0 | AC2: 0 | AF2: 1918 | AG2: 1918 | AO2: FALSE | AT2: 2 | AU2: 0.0054757016
A3: 1617 | B3: CZE-1918 | C3: 8217b290-1e42-11e4-b4cd-db5882bf8def | D3: 315 | E3: CZE | F3: =VLOOKUP(E3,country_continent!A:C,2,FALSE) -> Czechoslovakia | G3: =VLOOKUP(E3,country_continent!A:C,3,FALSE) -> Europe | H3: Masaryk | I3: 6876 | J3: =IF(ISNUMBER(SEARCH("-", I3)), SUBSTITUTE(I3, "-", "/"), I3) -> 6876 | K3: 13132 | L3: =IF(ISNUMBER(SEARCH("-", K3)), SUBSTITUTE(K3, "-", "/"), K3) -> 13132 | M3: Regular | N3: Retired Due to Ill Health | O3: Regular | P3: 0 | Q3: OK | R3: M | S3: 1850 | T3: 1937 | U3: 1850-03-07 | V3: 07mar1850 | W3: 13772 | X3: 13772 | Z3: 0 | AA3: 2.0999999 | AB3: 0 | AC3: 0 | AF3: 1918 | AG3: 1935 | AO3: FALSE | AT3: 6256 | AU3: 17.127995
A4: 1997 | B4: EST-1918 | C4: 8220a9b1-1e42-11e4-b4cd-db5882bf8def | D4: 366 | E4: EST | F4: =VLOOKUP(E4,country_continent!A:C,2,FALSE) -> Estonia | G4: =VLOOKUP(E4,country_continent!A:C,3,FALSE) -> Europe | H4: Pats | I4: 6630 | J4: =IF(ISNUMBER(SEARCH("-", I4)), SUBSTITUTE(I4, "-", "/"), I4) -> 6630 | K4: 7068 | L4: =IF(ISNUMBER(SEARCH("-", K4)), SUBSTITUTE(K4, "-", "/"), K4) -> 7068 | M4: Regular | N4: Regular | O4: Regular | P4: 0 | Q4: OK | R4: M | S4: 1874 | T4: 1956 | U4: 1874-02-23 | V4: 23feb1874 | W4: 20472 | X4: 20472 | Y4: https://urldefense.proofpoint.com/v2/url?u=http-3A__dbpedia.org_resource_Konstantin-5FP-25C3-25A4ts&d=BQID-g&c=kbmfwr1Yojg42sGEpaQh5ofMHBeTl9EI2eaqQZhHbOU&r=ZliGVSRwfirWoETOrKCh2RSnoygzVPWEk95Me9L-Kwo&m=EaKyFx9mpkhPdFxsxzvW_fiM3jbYwM3xYLjVbSFoDAg&s=Z8VLeAJDzsMikIwy1WxkA_aC2bDoaBhGCaAVPjFOc14&e= | Z4: 0 | AA4: 1 | AB4: 0 | AC4: 0 | AF4: 1918 | AG4: 1919 | AO4: FALSE | AT4: 438 | AU4: 1.1991786
A5: 1781 | B5: YUG-1918 | C5: 19777948-3bbd-11e5-afeb-eb6f07f9fec7 | D5: 345 | E5: YUG | F5: =VLOOKUP(E5,country_continent!A:C,2,FALSE) -> Yugoslavia | G5: =VLOOKUP(E5,country_continent!A:C,3,FALSE) -> Europe | H5: Alexander | I5: 6910 | J5: =IF(ISNUMBER(SEARCH("-", I5)), SUBSTITUTE(I5, "-", "/"), I5) -> 6910 | K5: 12701 | L5: =IF(ISNUMBER(SEARCH("-", K5)), SUBSTITUTE(K5, "-", "/"), K5) -> 12701 | M5: Regular | N5: Irregular | O5: Assassination by Unsupported Individual | P5: 1 | Q5: Death | R5: M | S5: 1888 | T5: 1934 | Y5: https://urldefense.proofpoint.com/v2/url?u=http-3A__dbpedia.org_resource_Alexander-5FI-5Fof-5FYugoslavia&d=BQID-g&c=kbmfwr1Yojg42sGEpaQh5ofMHBeTl9EI2eaqQZhHbOU&r=ZliGVSRwfirWoETOrKCh2RSnoygzVPWEk95Me9L-Kwo&m=EaKyFx9mpkhPdFxsxzvW_fiM3jbYwM3xYLjVbSFoDAg&s=hkCaRKRHNcAbMTxSSiT6HE4YSNHV1D49rupurgAtr5A&e= | Z5: 0 | AA5: 3 | AB5: 11 | AC5: 3 | AF5: 1918 | AG5: 1934 | AO5: FALSE | AT5: 5791 | AU5: 15.854894
A6: 2028 | B6: LAT-1918 | C6: 82216d01-1e42-11e4-b4cd-db5882bf8def | D6: 367 | E6: LAT | F6: =VLOOKUP(E6,country_continent!A:C,2,FALSE) -> Latvia | G6: =VLOOKUP(E6,country_continent!A:C,3,FALSE) -> Europe | H6: Ulmanis | I6: 6896 | J6: =IF(ISNUMBER(SEARCH("-", I6)), SUBSTITUTE(I6, "-", "/"), I6) -> 6896 | K6: 7051 | L6: =IF(ISNUMBER(SEARCH("-", K6)), SUBSTITUTE(K6, "-", "/"), K6) -> 7051 | M6: Irregular | N6: Regular | O6: Regular | P6: 0 | Q6: OK | R6: M | S6: 1877 | T6: 1942 | U6: 1877-09-04 | V6: 04sep1877 | Y6: https://urldefense.proofpoint.com/v2/url?u=http-3A__dbpedia.org_resource_K-25C4-2581rlis-5FUlmanis&d=BQID-g&c=kbmfwr1Yojg42sGEpaQh5ofMHBeTl9EI2eaqQZhHbOU&r=ZliGVSRwfirWoETOrKCh2RSnoygzVPWEk95Me9L-Kwo&m=EaKyFx9mpkhPdFxsxzvW_fiM3jbYwM3xYLjVbSFoDAg&s=5GenJdkFkhAPKjA4QxcYjNqG8XfHRTOpm7_k93yliQA&e= | Z6: 1 | AA6: 1 | AB6: 0 | AC6: 0 | AF6: 1918 | AG6: 1919 | AO6: FALSE | AT6: 155 | AU6: 0.42436687

Sheet country_continent
A1: Code | B1: Country | C1: Continent
A2: USA | B2: United States of America | C2: North America
A3: CAN | B3: Canada | C3: North America
A4: BHM | B4: The Bahamas | C4: North America
A5: CUB | B5: Cuba | C5: North America
A6: HAI | B6: Haiti | C6: North America
A7: DOM | B7: Dominican Republic | C7: North America
A8: JAM | B8: Jamaica | C8: North America
A9: TRI | B9: Trinidad and Tobago | C9: North America
A10: BAR | B10: Barbados | C10: North America
A11: MEX | B11: Mexico | C11: North America
A12: BLZ | B12: Belize | C12: North America
... A187: ERI | B187: Eritrea | C187: Africa
